Workbook

Sheet Dashboard
A1: Dashboard — Certificación IVA e IEPS
A4: Russell Bedford México · RGCE 2026 · Actualización automática
B6: 📋 Total de ítems | G6: ✅ Cumplidos | K6: Filtrar responsable:
B7: =COUNTIF(Req_Generales!B:B,"Pendiente")+COUNTIF(Req_Generales!B:B,"Cumplido")+COUNTIF(Req_Generales!B:B,"En riesgo")+COUNTIF(Req_Generales!B:B,"N/A")+COUNTIF(Req_Rubro!B:B,"Pendiente")+COUNTIF(Req_Rubro!B:B,"Cumplido")+COUNTIF(Req_Rubro!B:B,"En riesgo")+COUNTIF(Req_Rubro!B:B,"N/A")+COUNTIF(Solicitud_61LA!B:B,"Pendiente")+COUNTIF(Solicitud_61LA!B:B,"Cumplido")+COUNTIF(Solicitud_61LA!B:B,"En riesgo")+COUNTIF(Solicitud_61LA!B:B,"N/A") -> 101 | G7: =COUNTIF(Req_Generales!B:B,"Cumplido")+COUNTIF(Req_Rubro!B:B,"Cumplido")+COUNTIF(Solicitud_61LA!B:B,"Cumplido") -> 0 | K7: Todos
K10: (Selecciona un responsable para ver el conteo filtrado)
B12: ⚠️ En riesgo | G12: ⏳ Pendientes
B13: =COUNTIF(Req_Generales!B:B,"En riesgo")+COUNTIF(Req_Rubro!B:B,"En riesgo")+COUNTIF(Solicitud_61LA!B:B,"En riesgo") -> 0 | G13: =COUNTIF(Req_Generales!B:B,"Pendiente")+COUNTIF(Req_Rubro!B:B,"Pendiente")+COUNTIF(Solicitud_61LA!B:B,"Pendiente") -> 85
B18: 📎 Documentos adjuntos | G18: 📊 % de avance
B19: =COUNTIF(Req_Generales!E:E,"Adjunto")+COUNTIF(Req_Rubro!E:E,"Adjunto")+COUNTIF(Solicitud_61LA!E:E,"Adjunto") -> 0 | G19: =IFERROR((COUNTIF(Req_Generales!B:B,"Cumplido")+COUNTIF(Req_Rubro!B:B,"Cumplido")+COUNTIF(Solicitud_61LA!B:B,"Cumplido"))/(COUNTIF(Req_Generales!B:B,"Pendiente")+COUNTIF(Req_Generales!B:B,"Cumplido")+COUNTIF(Req_Generales!B:B,"En riesgo")+COUNTIF(Req_Generales!B:B,"N/A")+COUNTIF(Req_Rubro!B:B,"Pendiente")+COUNTIF(Req_Rubro!B:B,"Cumplido")+COUNTIF(Req_Rubro!B:B,"En riesgo")+COUNTIF(Req_Rubro!B:B,"N/A")+COUNTIF(Solicitud_61LA!B:B,"Pendiente")+COUNTIF(Solicitud_61LA!B:B,"Cumplido")+COUNTIF(Solicitud_61LA!B:B,"En riesgo")+COUNTIF(Solicitud_61LA!B:B,"N/A")),0) -> 0
K22: Por responsable:
J23: Cliente | K23: =IF($K$7="Todos",COUNTIF(Req_Generales!F:F,"Cliente")+COUNTIF(Req_Rubro!F:F,"Cliente")+COUNTIF(Solicitud_61LA!F:F,"Cliente"),IF($K$7="Cliente",COUNTIF(Req_Generales!F:F,"Cliente")+COUNTIF(Req_Rubro!F:F,"Cliente")+COUNTIF(Solicitud_61LA!F:F,"Cliente"),"-")) -> 0
J24: Asesor Russell Bedford | K24: =IF($K$7="Todos",COUNTIF(Req_Generales!F:F,"Asesor Russell Bedford")+COUNTIF(Req_Rubro!F:F,"Asesor Russell Bedford")+COUNTIF(Solicitud_61LA!F:F,"Asesor Russell Bedford"),IF($K$7="Asesor Russell Bedford",COUNTIF(Req_Generales!F:F,"Asesor Russell Bedford")+COUNTIF(Req_Rubro!F:F,"Asesor Russell Bedford")+COUNTIF(Solicitud_61LA!F:F,"Asesor Russell Bedford"),"-")) -> 0
J25: AGACE | K25: =IF($K$7="Todos",COUNTIF(Req_Generales!F:F,"AGACE")+COUNTIF(Req_Rubro!F:F,"AGACE")+COUNTIF(Solicitud_61LA!F:F,"AGACE"),IF($K$7="AGACE",COUNTIF(Req_Generales!F:F,"AGACE")+COUNTIF(Req_Rubro!F:F,"AGACE")+COUNTIF(Solicitud_61LA!F:F,"AGACE"),"-")) -> 0
J26: Otro | K26: =IF($K$7="Todos",COUNTIF(Req_Generales!F:F,"Otro")+COUNTIF(Req_Rubro!F:F,"Otro")+COUNTIF(Solicitud_61LA!F:F,"Otro"),IF($K$7="Otro",COUNTIF(Req_Generales!F:F,"Otro")+COUNTIF(Req_Rubro!F:F,"Otro")+COUNTIF(Solicitud_61LA!F:F,"Otro"),"-")) -> 0

Sheet Gantt
A1: Gantt — Certificación IVA e IEPS · Russell Bedford México
A2: ✅ Las barras se colorean automáticamente cuando marcas 'Cumplido' en las hojas · Solo define la fecha de inicio y fin de cada GRUPO (fila naranja)
A3: 📅 Fecha de inicio del proyecto: | D3: 46139
A4: ℹ️ Solo necesitas definir 'Inicio del grupo' y 'Fin del grupo' en las filas naranjas. Los ítems heredan esas fechas automáticamente.
A5: # | B5: Requisito / Ítem | C5: Responsable | D5: Inicio grupo | E5: Fin grupo | F5: Estatus | G5: S1 | H5: S2 | I5: S3 | J5: S4 | K5: S5 | L5: S6 | M5: S7 | N5: S8 | O5: S9 | P5: S10 | Q5: S11 | R5: S12 | S5: S13 | T5: S14 | U5: S15 | V5: S16 | W5: S17 | X5: S18 | Y5: S19 | Z5: S20
G6: =$D$3+0 -> 46139 | H6: =$D$3+7 -> 46146 | I6: =$D$3+14 -> 46153 | J6: =$D$3+21 -> 46160 | K6: =$D$3+28 -> 46167 | L6: =$D$3+35 -> 46174 | M6: =$D$3+42 -> 46181 | N6: =$D$3+49 -> 46188 | O6: =$D$3+56 -> 46195 | P6: =$D$3+63 -> 46202 | Q6: =$D$3+70 -> 46209 | R6: =$D$3+77 -> 46216 | S6: =$D$3+84 -> 46223 | T6: =$D$3+91 -> 46230 | U6: =$D$3+98 -> 46237 | V6: =$D$3+105 -> 46244 | W6: =$D$3+112 -> 46251 | X6: =$D$3+119 -> 46258 | Y6: =$D$3+126 -> 46265 | Z6: =$D$3+133 -> 46272
A7: ◆ 1. Requisitos generales
B8: 1. REQUISITOS GENERALES — Regla 7.1.1 | C8: ← Solo edita estas fechas | F8: GRUPO
B9: RGCE 2026 (DOF 27/12/2025) · Decreto IMMEX · Russell Bedford México | C9: ← Solo edita estas fechas | F9: GRUPO
B10: 1.1 Requisitos fiscales y legales | C10: ← Solo edita estas fechas | F10: GRUPO
A11: 1 | B11: =Req_Generales!C5 -> Personas morales constituidas conforme a la legislación mexicana | C11: =Req_Generales!F5 -> 0 | D11: =$D$10 -> 0 | E11: =$E$10 -> 0 | F11: =Req_Generales!B5 -> Pendiente
A12: 2 | B12: =Req_Generales!C6 -> Estar al corriente en obligaciones fiscales y aduaneras; autorizar al SAT para hacer pública la opinión positiva (Regla 2.1.24 RMF) | C12: =Req_Generales!F6 -> 0 | D12: =$D$10 -> 0 | E12: =$E$10 -> 0 | F12: =Req_Generales!B6 -> Pendiente
A13: 3 | B13: =Req_Generales!C7 -> Contar con certificados de sellos digitales vigentes y no ubicarse en supuestos del art. 17-H Bis CFF en los últimos 12 meses | C13: =Req_Generales!F7 -> 0 | D13: =$D$10 -> 0 | E13: =$E$10 -> 0 | F13: =Req_Generales!B7 -> Pendiente
A14: 4 | B14: =Req_Generales!C8 -> No estar en listados SAT: art. 69 CFF (exc. fracc. VI), art. 69-B cuarto párrafo, art. 69-B Bis noveno párrafo | C14: =Req_Generales!F8 -> 0 | D14: =$D$10 -> 0 | E14: =$E$10 -> 0 | F14: =Req_Generales!B8 -> Pendiente
A15: 5 | B15: =Req_Generales!C9 -> No haberse emitido resolución de emisión de falsos comprobantes fiscales (art. 49 Bis CFF) | C15: =Req_Generales!F9 -> 0 | D15: =$D$10 -> 0 | E15: =$E$10 -> 0 | F15: =Req_Generales!B9 -> Pendiente
A16: 6 | B16: =Req_Generales!C10 -> Socios, accionistas, representante legal e integrantes de administración al corriente en obligaciones fiscales | C16: =Req_Generales!F10 -> 0 | D16: =$D$10 -> 0 | E16: =$E$10 -> 0 | F16: =Req_Generales!B10 -> Pendiente
A17: 7 | B17: =Req_Generales!C11 -> Socios/accionistas y administración no vinculados con empresa a quien se le canceló el registro (regla 7.2.4) | C17: =Req_Generales!F11 -> 0 | D17: =$D$10 -> 0 | E17: =$E$10 -> 0 | F17: =Req_Generales!B11 -> Pendiente
A18: 8 | B18: =Req_Generales!C12 -> Ningún socio condenado por delitos que ameriten pena corporal | C18: =Req_Generales!F12 -> 0 | D18: =$D$10 -> 0 | E18: =$E$10 -> 0 | F18: =Req_Generales!B12 -> Pendiente
A19: 9 | B19: =Req_Generales!C13 -> Sin sanciones administrativas por importación o exportación de mercancías | C19: =Req_Generales!F13 -> 0 | D19: =$D$10 -> 0 | E19: =$E$10 -> 0 | F19: =Req_Generales!B13 -> Pendiente
A20: 10 | B20: =Req_Generales!C14 -> El SAT no haya interpuesto querella, denuncia penal o declaratoria de perjuicio contra socios/administración en los últimos 3 años | C20: =Req_Generales!F14 -> 0 | D20: =$D$10 -> 0 | E20: =$E$10 -> 0 | F20: =Req_Generales!B14 -> Pendiente
B21: 1.2 Domicilios e infraestructura | C21: ← Solo edita estas fechas | F21: GRUPO
A22: 11 | B22: =Req_Generales!C16 -> Tener registrados ante el SAT todos los domicilios vinculados al Programa IMMEX o actividades de comercio exterior | C22: =Req_Generales!F16 -> 0 | D22: =$D$21 -> 0 | E22: =$E$21 -> 0 | F22: =Req_Generales!B16 -> Pendiente
A23: 12 | B23: =Req_Generales!C17 -> Legal uso o goce del inmueble donde se realizan los procesos con vigencia forzosa mínima de 1 año y al menos 8 meses restantes a la solicitud | C23: =Req_Generales!F17 -> 0 | D23: =$D$21 -> 0 | E23: =$E$21 -> 0 | F23: =Req_Generales!B17 -> Pendiente
A24: 13 | B24: =Req_Generales!C18 -> Permitir en todo momento el acceso de la AGACE para visitas de inspección inicial y supervisión de cumplimiento | C24: =Req_Generales!F18 -> 0 | D24: =$D$21 -> 0 | E24: =$E$21 -> 0 | F24: =Req_Generales!B18 -> Pendiente
A25: 14 | B25: =Req_Generales!C19 -> No estar suspendido en el Padrón de Importadores, Padrón de Importadores de Sectores Específicos o Padrón de Exportadores Sectorial | C25: =Req_Generales!F19 -> 0 | D25: =$D$21 -> 0 | E25: =$E$21 -> 0 | F25: =Req_Generales!B19 -> Pendiente
B26: 1.3 Clientes, proveedores y contabilidad | C26: ← Solo edita estas fechas | F26: GRUPO
A27: 15 | B27: =Req_Generales!C21 -> Clientes y proveedores en el extranjero con operaciones de comercio exterior en los últimos 12 meses | C27: =Req_Generales!F21 -> 0 | D27: =$D$26 -> 0 | E27: =$E$26 -> 0 | F27: =Req_Generales!B21 -> Pendiente
A28: 16 | B28: =Req_Generales!C22 -> En su caso, proveedores de insumos en territorio nacional vinculados al proceso en los últimos 6 meses | C28: =Req_Generales!F22 -> 0 | D28: =$D$26 -> 0 | E28: =$E$26 -> 0 | F28: =Req_Generales!B22 -> Pendiente
A29: 17 | B29: =Req_Generales!C23 -> Llevar control de inventarios conforme al art. 59 fracc. I Ley Aduanera y Anexo 24 Apartado C | C29: =Req_Generales!F23 -> 0 | D29: =$D$26 -> 0 | E29: =$E$26 -> 0 | F29: =Req_Generales!B23 -> Pendiente
A30: 18 | B30: =Req_Generales!C24 -> Llevar contabilidad en medios electrónicos e ingresarla mensualmente al Portal SAT (CFF arts. 28 fracc. III y IV; RMF 2.8.1.5. y 2.8.1.6.) | C30: =Req_Generales!F24 -> 0 | D30: =$D$26 -> 0 | E30: =$E$26 -> 0 | F30: =Req_Generales!B24 -> Pendiente
A31: 19 | B31: =Req_Generales!C25 -> Contar con buzón tributario actualizado — estatus 'Validado' (CFF art. 17-K) | C31: =Req_Generales!F25 -> 0 | D31: =$D$26 -> 0 | E31: =$E$26 -> 0 | F31: =Req_Generales!B25 -> Pendiente
A32: 20 | B32: =Req_Generales!C26 -> Haber realizado el pago de derechos art. 40 inciso m) LFD (Anexo 4 RMF 2026) | C32: =Req_Generales!F26 -> 0 | D32: =$D$26 -> 0 | E32: =$E$26 -> 0 | F32: =Req_Generales!B26 -> Pendiente
B33: 1.4 Personal e IMSS | C33: ← Solo edita estas fechas | F33: GRUPO
A34: 21 | B34: =Req_Generales!C28 -> Personal registrado ante el IMSS para el proceso productivo/servicio; al corriente en cuotas obrero-patronales; retener y enterar ISR de trabajadores | C34: =Req_Generales!F28 -> 0 | D34: =$D$33 -> 0 | E34: =$E$33 -> 0 | F34: =Req_Generales!B28 -> Pendiente
A35: 22 | B35: =Req_Generales!C29 -> En caso de subcontratación de servicios especializados, cumplir con art. 27 fracc. V tercer párrafo de la Ley del ISR | C35: =Req_Generales!F29 -> 0 | D35: =$D$33 -> 0 | E35: =$E$33 -> 0 | F35: =Req_Generales!B29 -> Pendiente
A36: ◆ 2. Requisitos por rubro
B37: 2. REQUISITOS POR RUBRO — Reglas 7.1.2 y 7.1.3 | C37: ← Solo edita estas fechas | F37: GRUPO
B38: RGCE 2026 (DOF 27/12/2025) · Decreto IMMEX · Russell Bedford México | C38: ← Solo edita estas fechas | F38: GRUPO
B39: Rubro A — Regla 7.1.2 (además de todos los requisitos de la regla 7.1.1) | C39: ← Solo edita estas fechas | F39: GRUPO
A40: 23 | B40: =Req_Rubro!C5 -> Presentar solicitud mediante ficha de trámite 61/LA (Anexo 2) | C40: =Req_Rubro!F5 -> 0 | D40: =$D$39 -> 0 | E40: =$E$39 -> 0 | F40: =Req_Rubro!B5 -> Pendiente
...

Sheet Resumen
A1: Russell Bedford México
A2: Checklist — Certificación IVA e IEPS · RGCE 2026 (DOF 27/12/2025)
A4: AVANCE GLOBAL DEL PROYECTO
A5: =TEXT(E12,"0%")&" completado | "&TEXT(C12,"0")&" cumplidos de "&TEXT(B12,"0")&" ítems | "&TEXT(F12,"0")&" documentos adjuntos | "&TEXT(G12,"0")&" fechas registradas" -> 0% completado | 0 cumplidos de 101 ítems | 0 documentos adjuntos | 0 fechas registradas
A7: SECCIÓN PARA EL CLIENTE — Obtención del Registro
A8: Sección | B8: Total | C8: ✓ Cumplidos | D8: ⚠ En riesgo | E8: % Avance | F8: ✓ Adjuntos | G8: 📅 Con fecha
A9: 1. Requisitos generales (Regla 7.1.1) | B9: =COUNTIF(Req_Generales!B:B,"Pendiente")+COUNTIF(Req_Generales!B:B,"Cumplido")+COUNTIF(Req_Generales!B:B,"En riesgo")+COUNTIF(Req_Generales!B:B,"N/A") -> 22 | C9: =COUNTIF(Req_Generales!B:B,"Cumplido") -> 0 | D9: =COUNTIF(Req_Generales!B:B,"En riesgo") -> 0 | E9: =IF(B9=0,0,C9/B9) -> 0 | F9: =COUNTIF(Req_Generales!E:E,"Adjunto") -> 0 | G9: =COUNTA(Req_Generales!G:G)-1 -> 0
A10: 2. Requisitos por rubro (Reglas 7.1.2 y 7.1.3) | B10: =COUNTIF(Req_Rubro!B:B,"Pendiente")+COUNTIF(Req_Rubro!B:B,"Cumplido")+COUNTIF(Req_Rubro!B:B,"En riesgo")+COUNTIF(Req_Rubro!B:B,"N/A") -> 16 | C10: =COUNTIF(Req_Rubro!B:B,"Cumplido") -> 0 | D10: =COUNTIF(Req_Rubro!B:B,"En riesgo") -> 0 | E10: =IF(B10=0,0,C10/B10) -> 0 | F10: =COUNTIF(Req_Rubro!E:E,"Adjunto") -> 0 | G10: =COUNTA(Req_Rubro!G:G)-1 -> 0
A11: 6. Solicitud de registro / Renovación (Ficha 61/LA) | B11: =COUNTIF(Solicitud_61LA!B:B,"Pendiente")+COUNTIF(Solicitud_61LA!B:B,"Cumplido")+COUNTIF(Solicitud_61LA!B:B,"En riesgo")+COUNTIF(Solicitud_61LA!B:B,"N/A") -> 63 | C11: =COUNTIF(Solicitud_61LA!B:B,"Cumplido") -> 0 | D11: =COUNTIF(Solicitud_61LA!B:B,"En riesgo") -> 0 | E11: =IF(B11=0,0,C11/B11) -> 0 | F11: =COUNTIF(Solicitud_61LA!E:E,"Adjunto") -> 0 | G11: =COUNTA(Solicitud_61LA!G:G)-1 -> 0
A12: SUBTOTAL — Sección cliente | B12: =SUM(B9:B11) -> 101 | C12: =SUM(C9:C11) -> 0 | D12: =SUM(D9:D11) -> 0 | E12: =IF(B12=0,0,C12/B12) -> 0 | F12: =SUM(F9:F11) -> 0 | G12: =SUM(G9:G11) -> 0
A14: SECCIÓN INTERNA — Referencia Russell Bedford (no aplica para solicitud inicial)
A15: ℹ️ Estas secciones corresponden a obligaciones permanentes y causales de requerimiento/cancelación. Se usan como referencia de cumplimiento continuo, no para la solicitud inicial de certificación.
A16: Sección | B16: Total | C16: ✓ Cumplidos | D16: ⚠ En riesgo | E16: % Avance
A17: 3. Obligaciones permanentes (Regla 7.2.1 + Decreto IMMEX) | B17: =COUNTIF(Obligaciones!B:B,"Pendiente")+COUNTIF(Obligaciones!B:B,"Cumplido")+COUNTIF(Obligaciones!B:B,"En riesgo")+COUNTIF(Obligaciones!B:B,"N/A") -> 18 | C17: =COUNTIF(Obligaciones!B:B,"Cumplido") -> 0 | D17: =COUNTIF(Obligaciones!B:B,"En riesgo") -> 0 | E17: =IF(B17=0,0,C17/B17) -> 0 | F17: N/A | G17: N/A
A18: 4. Causas de requerimiento (Regla 7.2.2) | B18: =COUNTIF(Requerimiento!B:B,"Pendiente")+COUNTIF(Requerimiento!B:B,"Cumplido")+COUNTIF(Requerimiento!B:B,"En riesgo")+COUNTIF(Requerimiento!B:B,"N/A") -> 16 | C18: =COUNTIF(Requerimiento!B:B,"Cumplido") -> 0 | D18: =COUNTIF(Requerimiento!B:B,"En riesgo") -> 0 | E18: =IF(B18=0,0,C18/B18) -> 0 | F18: N/A | G18: N/A
A19: 5. Causas de cancelación y suspensión (Regla 7.2.4) | B19: =COUNTIF(Cancelacion!B:B,"Pendiente")+COUNTIF(Cancelacion!B:B,"Cumplido")+COUNTIF(Cancelacion!B:B,"En riesgo")+COUNTIF(Cancelacion!B:B,"N/A") -> 20 | C19: =COUNTIF(Cancelacion!B:B,"Cumplido") -> 0 | D19: =COUNTIF(Cancelacion!B:B,"En riesgo") -> 0 | E19: =IF(B19=0,0,C19/B19) -> 0 | F19: N/A | G19: N/A
A20: SUBTOTAL — Sección interna | B20: =SUM(B17:B19) -> 54 | C20: =SUM(C17:C19) -> 0 | D20: =SUM(D17:D19) -> 0 | E20: =IF(B20=0,0,C20/B20) -> 0 | F20: — | G20: —
A22: LEYENDA
A23: Columna Estatus (col B) | D23: Columna Documento / Responsable / Fecha (cols E, F, G)
A24: Pendiente | C24: Ítem no revisado aún | D24: Sin documento | E24: Falta documento de soporte
A25: Cumplido | C25: Requisito acreditado | D25: Adjunto | E25: Documento localizado y adjunto
A26: En riesgo | C26: Requiere atención inmediata | D26: No aplica | E26: No se requiere documento
A27: N/A | C27: No aplica para este caso | D27: Responsable | E27: Cliente / Asesor RB / AGACE / Otro
A29: Elaborado con base en RGCE DOF 27/12/2025 y Decreto IMMEX vigente · Russell Bedford México · www.russellbedford.com.mx

Sheet Req_Generales
A1: 1. REQUISITOS GENERALES — Regla 7.1.1
A2: RGCE 2026 (DOF 27/12/2025) · Decreto IMMEX · Russell Bedford México
A3: # | B3: Estatus | C3: Requisito / Obligación / Causal | D3: Referencia normativa | E3: Documento / Evidencia de cumplimiento | F3: Responsable | G3: Fecha de cumplimiento
A4: 1.1 Requisitos fiscales y legales
A5: 1 | B5: Pendiente | C5: Personas morales constituidas conforme a la legislación mexicana | D5: 7.1.1 fracc. I
A6: 2 | B6: Pendiente | C6: Estar al corriente en obligaciones fiscales y aduaneras; autorizar al SAT para hacer pública la opinión positiva (Regla 2.1.24 RMF) | D6: 7.1.1 fracc. II · CFF art. 32-D
A7: 3 | B7: Pendiente | C7: Contar con certificados de sellos digitales vigentes y no ubicarse en supuestos del art. 17-H Bis CFF en los últimos 12 meses | D7: 7.1.1 fracc. V · CFF art. 17-H Bis
A8: 4 | B8: Pendiente | C8: No estar en listados SAT: art. 69 CFF (exc. fracc. VI), art. 69-B cuarto párrafo, art. 69-B Bis noveno párrafo | D8: 7.1.1 fracc. IV · CFF arts. 69, 69-B, 69-B Bis
A9: 5 | B9: Pendiente | C9: No haberse emitido resolución de emisión de falsos comprobantes fiscales (art. 49 Bis CFF) | D9: 7.1.1 fracc. XXI · CFF art. 49 Bis
A10: 6 | B10: Pendiente | C10: Socios, accionistas, representante legal e integrantes de administración al corriente en obligaciones fiscales | D10: 7.1.1 fracc. XVI
A11: 7 | B11: Pendiente | C11: Socios/accionistas y administración no vinculados con empresa a quien se le canceló el registro (regla 7.2.4) | D11: 7.1.1 fracc. XVII · Regla 7.2.4
A12: 8 | B12: Pendiente | C12: Ningún socio condenado por delitos que ameriten pena corporal | D12: 7.1.1 fracc. XVIII
A13: 9 | B13: Pendiente | C13: Sin sanciones administrativas por importación o exportación de mercancías | D13: 7.1.1 fracc. XIX
A14: 10 | B14: Pendiente | C14: El SAT no haya interpuesto querella, denuncia penal o declaratoria de perjuicio contra socios/administración en los últimos 3 años | D14: 7.1.1 fracc. XIII
A15: 1.2 Domicilios e infraestructura
A16: 11 | B16: Pendiente | C16: Tener registrados ante el SAT todos los domicilios vinculados al Programa IMMEX o actividades de comercio exterior | D16: 7.1.1 fracc. VI · CFF art. 27
A17: 12 | B17: Pendiente | C17: Legal uso o goce del inmueble donde se realizan los procesos con vigencia forzosa mínima de 1 año y al menos 8 meses restantes a la solicitud | D17: 7.1.1 fracc. XII
A18: 13 | B18: Pendiente | C18: Permitir en todo momento el acceso de la AGACE para visitas de inspección inicial y supervisión de cumplimiento | D18: 7.1.1 fracc. IX
A19: 14 | B19: Pendiente | C19: No estar suspendido en el Padrón de Importadores, Padrón de Importadores de Sectores Específicos o Padrón de Exportadores Sectorial | D19: 7.1.1 fracc. VIII
A20: 1.3 Clientes, proveedores y contabilidad
A21: 15 | B21: Pendiente | C21: Clientes y proveedores en el extranjero con operaciones de comercio exterior en los últimos 12 meses | D21: 7.1.1 fracc. X
A22: 16 | B22: Pendiente | C22: En su caso, proveedores de insumos en territorio nacional vinculados al proceso en los últimos 6 meses | D22: 7.1.1 fracc. XI
A23: 17 | B23: Pendiente | C23: Llevar control de inventarios conforme al art. 59 fracc. I Ley Aduanera y Anexo 24 Apartado C | D23: 7.1.1 fracc. XIV · LA art. 59
A24: 18 | B24: Pendiente | C24: Llevar contabilidad en medios electrónicos e ingresarla mensualmente al Portal SAT (CFF arts. 28 fracc. III y IV; RMF 2.8.1.5. y 2.8.1.6.) | D24: 7.1.1 fracc. XV
A25: 19 | B25: Pendiente | C25: Contar con buzón tributario actualizado — estatus 'Validado' (CFF art. 17-K) | D25: 7.1.1 fracc. VII · CFF art. 17-K
A26: 20 | B26: Pendiente | C26: Haber realizado el pago de derechos art. 40 inciso m) LFD (Anexo 4 RMF 2026) | D26: 7.1.1 fracc. XX · LFD art. 40
A27: 1.4 Personal e IMSS
A28: 21 | B28: Pendiente | C28: Personal registrado ante el IMSS para el proceso productivo/servicio; al corriente en cuotas obrero-patronales; retener y enterar ISR de trabajadores | D28: 7.1.1 fracc. III · ISR art. 27
A29: 22 | B29: Pendiente | C29: En caso de subcontratación de servicios especializados, cumplir con art. 27 fracc. V tercer párrafo de la Ley del ISR | D29: 7.1.1 fracc. III · ISR art. 27 fracc. V

Sheet Req_Rubro
A1: 2. REQUISITOS POR RUBRO — Reglas 7.1.2 y 7.1.3
A2: RGCE 2026 (DOF 27/12/2025) · Decreto IMMEX · Russell Bedford México
A3: # | B3: Estatus | C3: Requisito / Obligación / Causal | D3: Referencia normativa | E3: Documento / Evidencia de cumplimiento | F3: Responsable | G3: Fecha de cumplimiento
A4: Rubro A — Regla 7.1.2 (además de todos los requisitos de la regla 7.1.1)
A5: 1 | B5: Pendiente | C5: Presentar solicitud mediante ficha de trámite 61/LA (Anexo 2) | D5: 7.1.2 fracc. I
A6: 2 | B6: Pendiente | C6: Mínimo 10 trabajadores registrados ante el IMSS y pago total de cuotas obrero-patronales | D6: 7.1.2 fracc. II
A7: 3 | B7: Pendiente | C7: Acreditar inversión en territorio nacional | D7: 7.1.2 fracc. III
A8: 4 | B8: Pendiente | C8: Si anteriormente tuvo el registro o garantizó el interés fiscal, estar al corriente con obligaciones del Anexo 30 (SCCCyG) | D8: 7.1.2 fracc. IV · Anexo 30
A9: 5 | B9: Pendiente | C9: Proveedores no incluidos en listados SAT arts. 49 Bis fracc. X o 69-B cuarto párrafo CFF | D9: 7.1.2 fracc. V
A10: 6 | B10: Pendiente | C10: Contar con Programa IMMEX vigente | D10: 7.1.2 Apt. A, fracc. I
A11: 7 | B11: Pendiente | C11: Infraestructura suficiente para realizar la operación del Programa IMMEX conforme a su modalidad | D11: 7.1.2 Apt. A, fracc. II
A12: 8 | B12: Pendiente | C12: Haber importado temporalmente y retornado en los últimos 12 meses: ≥60% del valor total de importaciones temporales de insumos (elaboración/transformación/reparación) o ≥60% para otros objetos | D12: 7.1.2 Apt. A, fracc. III
A13: 9 | B13: Pendiente | C13: Describir actividades del proceso productivo desde el arribo, almacenamiento, proceso y retorno de mercancías | D13: 7.1.2 Apt. A, fracc. IV
A14: 10 | B14: Pendiente | C14: Contrato de maquila, compraventa, orden de compra, servicios o pedidos en firme que acrediten continuidad del proyecto de exportación | D14: 7.1.2 Apt. A, fracc. V
A15: Rubro AA — Regla 7.1.3 (además de todos los requisitos del Rubro A)
A16: 11 | B16: Pendiente | C16: ≥4 años operando bajo el régimen solicitado, O promedio >1,000 trabajadores en los últimos 12 meses, O maquinaria y equipo con valor >$50,000,000 pesos | D16: 7.1.3 fracc. I inciso a)
A17: 12 | B17: Pendiente | C17: Sin crédito fiscal notificado por el SAT en los últimos 12 meses (o garantizado conforme art. 141 CFF / pago a plazos sin exceder 12 meses) | D17: 7.1.3 fracc. I inciso b)
A18: 13 | B18: Pendiente | C18: Sin resolución de improcedencia de devolución IVA >20% del total autorizado y/o monto negado >$5,000,000 pesos en los últimos 6 meses | D18: 7.1.3 fracc. I inciso c)
A19: Rubro AAA — Regla 7.1.3 (además de todos los requisitos del Rubro AA)
A20: 14 | B20: Pendiente | C20: ≥7 años operando bajo el régimen solicitado, O promedio >2,500 trabajadores en los últimos 12 meses, O maquinaria y equipo con valor >$100,000,000 pesos | D20: 7.1.3 fracc. II inciso a)
A21: 15 | B21: Pendiente | C21: Sin crédito fiscal notificado por el SAT en los últimos 24 meses (o garantizado conforme art. 141 CFF) | D21: 7.1.3 fracc. II inciso b)
A22: 16 | B22: Pendiente | C22: Sin resolución de improcedencia de devolución IVA >20% del total autorizado y/o monto negado >$5,000,000 pesos en los últimos 6 meses | D22: 7.1.3 fracc. II inciso c)

Sheet Solicitud_61LA
A1: 6. SOLICITUD DE REGISTRO / RENOVACIÓN — Ficha 61/LA
A2: RGCE 2026 (DOF 27/12/2025) · Decreto IMMEX · Russell Bedford México
A3: # | B3: Estatus | C3: Requisito / Obligación / Causal | D3: Referencia normativa | E3: Documento / Evidencia de cumplimiento | F3: Responsable | G3: Fecha de cumplimiento
A4: Información general del trámite
A5: 1 | B5: Pendiente | C5: Pago de derechos: $40,267.00 a través del esquema electrónico e5cinco. El aviso de renovación es gratuito. | D5: 61/LA · Monto
A6: 2 | B6: Pendiente | C6: Pueden solicitarlo personas físicas o morales | D6: 61/LA · ¿Quién?
A7: 3 | B7: Pendiente | C7: Se presenta en la Ventanilla Digital: https://www.ventanillaunica.gob.mx | D7: 61/LA · ¿Dónde?
A8: 4 | B8: Pendiente | C8: Para obtener el registro: presentar cuando se desee. Para renovación: presentar 30 días previos al vencimiento de la vigencia | D8: 61/LA · ¿Cuándo?
A9: 5 | B9: Pendiente | C9: Vigencia: IVA e IEPS = 1 año; Comercializadora e Importadora / OEA / Socio Comercial Certificado = 2 años | D9: 61/LA · Vigencia
A10: 6 | B10: Pendiente | C10: Plazo SAT para resolver: IVA e IEPS y Comercializadora e Importadora = 60 días; OEA y Socio Comercial Certificado = 120 días | D10: 61/LA · Resolución
A11: 7 | B11: Pendiente | C11: Plazo para cumplir información adicional solicitada por el SAT: 15 días. De no cumplir, la solicitud se tiene por no presentada | D11: 61/LA · Info adicional
A12: 8 | B12: Pendiente | C12: La autoridad podrá realizar visita de inspección inicial para constatar el cumplimiento de requisitos y obligaciones | D12: 61/LA · Inspección
A13: A.I Documentos generales — todas las modalidades
A14: 9 | B14: Pendiente | C14: Documento que acredite la relación laboral de los enlaces operativos (recibo de nómina, contrato laboral o carta firmada por el representante legal) | D14: 61/LA Apt.A fracc.I inciso a)
A15: 10 | B15: Pendiente | C15: Registros patronales y constancias de la totalidad del personal registrado ante el IMSS del SUA, del último bimestre anterior a la solicitud. Para rubro A: primeras y últimas hojas de al menos 10 trabajadores + listado nombre/RFC | D15: 61/LA Apt.A fracc.I inciso b)
A16: 11 | B16: Pendiente | C16: Última declaración de retenciones de ISR por salarios + comprobante del entero de las contribuciones retenidas de trabajadores | D16: 61/LA Apt.A fracc.I inciso c)
A17: 12 | B17: Pendiente | C17: Comprobante de pago SIPARE (o acorde al SUA) de cuotas obrero-patronales del último bimestre. Nota: no son válidos comprobantes con leyenda de que no tienen efectos fiscales o legales | D17: 61/LA Apt.A fracc.I inciso d)
A18: 13 | B18: Pendiente | C18: En caso de subcontratación de servicios especializados: documentación que acredite el cumplimiento del art. 27 fracc. V tercer párrafo Ley ISR | D18: 61/LA Apt.A fracc.I inciso d) párr.2
A19: 14 | B19: Pendiente | C19: Listado de clientes y proveedores en el extranjero (nombre, denominación y domicilio), vinculados al régimen solicitado, con operaciones de CE en los últimos 12 meses, distinguiendo rol (cliente/proveedor) | D19: 61/LA Apt.A fracc.I inciso e)
A20: 15 | B20: Pendiente | C20: Listado de proveedores de insumos en territorio nacional (nombre y RFC), vinculados al proceso del régimen solicitado, de los últimos 6 meses. Si no hay, escrito libre bajo protesta de decir verdad del representante legal | D20: 61/LA Apt.A fracc.I inciso f)
A21: 16 | B21: Pendiente | C21: Contrato o título de propiedad del inmueble donde se realizan los procesos productivos, con vigencia forzosa ≥1 año y al menos 8 meses restantes. En subarrendamiento: contrato principal + autorización general para subarrendar | D21: 61/LA Apt.A fracc.I inciso g)
A22: 17 | B22: Pendiente | C22: Reporte de saldos de mercancías de importación temporal de un mes (dentro de los últimos 3 meses previos a la solicitud), con: número de pedimento, fecha de pago/entrada, clave de pedimento, fracción arancelaria, cantidad, valor, saldo y valor del saldo | D22: 61/LA Apt.A fracc.I inciso h)
A23: 18 | B23: Pendiente | C23: Listado de socios, accionistas, representantes legales con facultad para actos de dominio e integrantes de la administración obligados a tributar en México | D23: 61/LA Apt.A fracc.I inciso i)
A24: 19 | B24: Pendiente | C24: Socios/accionistas NO obligados a tributar en México: Forma Oficial 96 (ficha 39/CFF) del ejercicio en curso o último ejercicio + acuse de presentación ante el SAT | D24: 61/LA Apt.A fracc.I inciso i) párr.2
A25: 20 | B25: Pendiente | C25: Representante legal / administrador único / consejo de administración NO obligados a tributar en México: opinión 'Sin obligaciones fiscales', constancia de residencia fiscal, declaraciones del país donde tributan o pasaporte | D25: 61/LA Apt.A fracc.I inciso i) párr.3
... A28: 23 | B28: Pendiente | C28: Recibo de pago de derechos con sello digital o comprobante e5cinco ($40,267.00). Liga: https://aplicacionesc.mat.sat.gob.mx/e5cinco/ | D28: 61/LA Apt.A fracc.I inciso l)
A29: A.II Documentos adicionales — Rubro A (IVA e IEPS)
A30: 24 | B30: Pendiente | C30: CFDI, título de propiedad, pedimentos de importación o contratos que acrediten el legal uso o goce de maquinaria y equipo + CFDI que amparen el pago | D30: 61/LA fracc.II inciso a) num.1 rom.i
A31: 25 | B31: Pendiente | C31: Fotografías de la planta productiva y del proceso productivo | D31: 61/LA fracc.II inciso a) num.1 rom.ii
A32: 26 | B32: Pendiente | C32: Si se declararon constancias de transferencia de mercancías: 2 constancias + Excel con nombres, domicilios y montos de las empresas receptoras | D32: 61/LA fracc.II inciso a) num.1 rom.iii
A33: 27 | B33: Pendiente | C33: Diagrama de flujo detallado del principal proceso productivo (origen, entrada al país, recepción, materiales con fracción arancelaria, almacenamiento, proceso, salida, destino/descargo y submanufactura) | D33: 61/LA fracc.II inciso a) num.1 rom.iv
A34: 28 | B34: Pendiente | C34: Contrato de maquila, compraventa, orden de compra, de servicios o pedidos en firme vigentes, con razón social, vigencia, firmas de las partes y traducción al español si aplica | D34: 61/LA fracc.II inciso a) num.1 rom.v
A35: 29 | B35: Pendiente | C35: Para importación de mercancías del Anexo II Decreto IMMEX o Anexo 28 RGCE: documentación que acredite operaciones al amparo del IMMEX en al menos los 12 meses previos a la solicitud | D35: 61/LA fracc.II inciso a) num.2 rom.i
A36: A.II Documentos adicionales — Rubro AA (IVA e IEPS)
A37: 30 | B37: N/A | C37: Acreditar al menos UNO de: constancias de más de 1,000 empleados ante IMSS/SUA de los últimos 12 meses, O declaración fiscal/CFDI/título con valor de maquinaria y equipo ≥$50,000,000 pesos | D37: 61/LA fracc.II inciso b)
A38: 31 | B38: N/A | C38: Si hay crédito fiscal del SAT en los últimos 12 meses: adjuntar autorización de pago a plazos (parcialidades o diferido) + comprobante de pago | D38: 61/LA fracc.II inciso b) párr.2
A39: A.II Documentos adicionales — Rubro AAA (IVA e IEPS)
A40: 32 | B40: N/A | C40: Acreditar al menos UNO de: constancias de más de 2,500 empleados ante IMSS/SUA de los últimos 12 meses, O documentos con valor de maquinaria y equipo ≥$100,000,000 pesos, O listado de proveedores de insumos nacionales o empresas que transfieren mercancías (valores de los últimos 6 meses) | D40: 61/LA fracc.II inciso c)
A41: A.III Documentos — Modalidad Comercializadora e Importadora
A42: 33 | B42: N/A | C42: Documentación que acredite importaciones en el semestre inmediato anterior con valor en aduana no menor a $300,000,000 pesos | D42: 61/LA Apt.A fracc.III
...

Sheet Obligaciones
A1: 3. OBLIGACIONES PERMANENTES — Regla 7.2.1 y Decreto IMMEX
A2: RGCE 2026 (DOF 27/12/2025) · Decreto IMMEX · Russell Bedford México
A3: # | B3: Estatus | C3: Requisito / Obligación / Causal | D3: Referencia normativa | E3: Documento / Evidencia de cumplimiento
A4: 3.1 Obligaciones generales (todos los registros)
A5: 1 | B5: N/A | C5: Cumplir permanentemente con los requisitos del rubro otorgado | D5: 7.2.1 fracc. I
A6: 2 | B6: N/A | C6: Estar permanentemente al corriente en obligaciones fiscales y aduaneras | D6: 7.2.1 fracc. II
A7: 3 | B7: N/A | C7: Dar aviso de cambio en el documento de legal uso y goce del inmueble (vigencia, partes, domicilio) mediante ficha 62/LA | D7: 7.2.1 fracc. VIII
A8: 4 | B8: N/A | C8: Presentar aviso previo al menos 1 mes antes de introducir mercancías adicionales a las declaradas, mediante ficha 62/LA | D8: 7.2.1 fracc. X
A9: 5 | B9: N/A | C9: Permitir en todo momento el acceso de la autoridad aduanera para inspecciones de supervisión de cumplimiento | D9: 7.2.1 fracc. VII
A10: 6 | B10: N/A | C10: En caso de fusión/escisión: dar aviso ante la AGACE dentro de los 10 días posteriores a la inscripción en el Registro Público de Comercio — ficha 62/LA | D10: 7.2.1 fracc. V
A11: 3.2 Obligaciones específicas modalidad IVA e IEPS (rubros A, AA y AAA)
A12: 7 | B12: N/A | C12: Reportar mensualmente a la AGACE (mes siguiente) modificaciones de socios, accionistas, representante legal, clientes y proveedores extranjeros, y proveedores nacionales | D12: 7.2.1 segundo párrafo fracc. I
A13: 8 | B13: N/A | C13: Acreditar continuidad del legal uso y goce del inmueble para los procesos productivos | D13: 7.2.1 segundo párrafo fracc. II
A14: 9 | B14: N/A | C14: Estar permanentemente al corriente en el pago de cuotas obrero-patronales ante el IMSS | D14: 7.2.1 segundo párrafo fracc. III
A15: 10 | B15: N/A | C15: Transmitir electrónicamente (Anexo 30 / Portal SAT) informes de descargo: retornos, cambios de régimen, transferencias virtuales, extracciones, regularizaciones, donaciones y destrucciones en el SCCCyG | D15: 7.2.1 segundo párrafo fracc. IV · Anexo 30
A16: 11 | B16: N/A | C16: Transmitir inventario de mercancías y/o activo fijo pendiente de retorno en un plazo máximo de 30 días naturales posteriores a la fecha de certificación | D16: 7.2.1 segundo párrafo fracc. IV
A17: 3.3 Obligaciones adicionales — Decreto IMMEX (arts. 24 y 25)
A18: 12 | B18: N/A | C18: Realizar anualmente exportaciones por más de USD $500,000 o que representen ≥10% de la facturación total | D18: IMMEX art. 24 fracc. I
A19: 13 | B19: N/A | C19: Destinar las mercancías importadas temporalmente únicamente a los fines autorizados en el Programa | D19: IMMEX art. 24 fracc. IV
A20: 14 | B20: N/A | C20: Retornar las mercancías en los plazos establecidos en la Ley o el Decreto IMMEX | D20: IMMEX art. 24 fracc. V
A21: 15 | B21: N/A | C21: Mantener las mercancías importadas temporalmente en los domicilios registrados en el Programa | D21: IMMEX art. 24 fracc. VI
A22: 16 | B22: N/A | C22: Notificar a la SE los cambios de socios, accionistas o representante legal | D22: IMMEX art. 24 fracc. VIII
A23: 17 | B23: N/A | C23: Llevar control de inventarios automatizado conforme a las RGCE | D23: IMMEX art. 24 fracc. IX
A24: 18 | B24: N/A | C24: Presentar reporte anual electrónico a la SE de ventas totales y exportaciones del ejercicio anterior, a más tardar el último día hábil de mayo | D24: IMMEX art. 25

Sheet Requerimiento
A1: 4. CAUSAS DE REQUERIMIENTO — Regla 7.2.2
A2: RGCE 2026 (DOF 27/12/2025) · Decreto IMMEX · Russell Bedford México
A3: # | B3: Estatus | C3: Requisito / Obligación / Causal | D3: Referencia normativa | E3: Documento / Evidencia de cumplimiento
A4: ℹ️ Nota: La AGACE otorga 20 días hábiles para subsanar o desvirtuar. Si no se subsana, se inicia el procedimiento de cancelación. La AGACE tiene 6 meses para emitir resolución.
A5: 4.1 Causas generales (todos los registros)
A6: 1 | B6: N/A | C6: La empresa no está al corriente en el cumplimiento de obligaciones fiscales | D6: 7.2.2 fracc. I inciso a)
A7: 2 | B7: N/A | C7: Incumplimiento de la obligación de retener y enterar el ISR de trabajadores | D7: 7.2.2 fracc. I inciso b)
A8: 3 | B8: N/A | C8: Ubicarse en los listados del SAT: art. 69 CFF (exc. fracc. VI), art. 69-B cuarto párrafo, o art. 69-B Bis noveno párrafo | D8: 7.2.2 fracc. I inciso c)
A9: 4 | B9: N/A | C9: Ubicarse en causales del art. 17-H Bis del CFF (restricción de sellos digitales) | D9: 7.2.2 fracc. I inciso d)
A10: 5 | B10: N/A | C10: Dejar de cumplir con las obligaciones establecidas en la regla 7.2.1 | D10: 7.2.2 fracc. I inciso e)
A11: 6 | B11: N/A | C11: No haber realizado el pago de derechos anual o por renovación (art. 40 inciso m) LFD, esquema e5cinco) | D11: 7.2.2 fracc. I inciso f)
A12: 7 | B12: N/A | C12: Haberse emitido y notificado resolución de emisión de falsos comprobantes fiscales (art. 49 Bis CFF) | D12: 7.2.2 fracc. I inciso g)
A13: 4.2 Causas específicas para rubros A, AA y AAA
A14: 8 | B14: N/A | C14: Socios, accionistas, representante legal o administración no al corriente en obligaciones fiscales | D14: 7.2.2 fracc. II inciso a)
A15: 9 | B15: N/A | C15: Personal insuficiente, no registrado en IMSS, no al corriente en cuotas o sin retención/entero de ISR; en subcontratación, omisión art. 27 fracc. V Ley ISR | D15: 7.2.2 fracc. II inciso b)
A16: 10 | B16: N/A | C16: Proveedores nacionales de insumos no al corriente en obligaciones fiscales | D16: 7.2.2 fracc. II inciso c)
A17: 11 | B17: N/A | C17: Dejar de acreditar el legal uso y goce del inmueble para los procesos productivos | D17: 7.2.2 fracc. II inciso d)
A18: 12 | B18: N/A | C18: Rubro AA o AAA: determinación y notificación de un crédito fiscal | D18: 7.2.2 fracc. II inciso e)
A19: 13 | B19: N/A | C19: Resoluciones de improcedencia de devolución de IVA >20% del total autorizado y/o monto negado >$5,000,000 pesos en los últimos 6 meses | D19: 7.2.2 fracc. II inciso f)
A20: 14 | B20: N/A | C20: No transmisión del informe de inventario existente o inicial, o de informes de descargo conforme al Anexo 30 | D20: 7.2.2 fracc. II inciso g)
A21: 15 | B21: N/A | C21: Control de inventarios no conforme al art. 59 fracc. I Ley Aduanera y disposiciones del SAT | D21: 7.2.2 fracc. II inciso h)
A22: 16 | B22: N/A | C22: Proveedores en listados SAT: art. 49 Bis fracc. X o art. 69-B cuarto párrafo CFF | D22: 7.2.2 fracc. II inciso i)

Sheet Cancelacion
A1: 5. CAUSAS DE CANCELACIÓN Y SUSPENSIÓN — Regla 7.2.4
A2: RGCE 2026 (DOF 27/12/2025) · Decreto IMMEX · Russell Bedford México
A3: # | B3: Estatus | C3: Requisito / Obligación / Causal | D3: Referencia normativa | E3: Documento / Evidencia de cumplimiento
A4: ℹ️ Nota: La AGACE notifica el inicio del procedimiento; el contribuyente tiene 10 días para ofrecer pruebas y alegatos. La resolución debe emitirse en ≤4 meses. Los cancelados no podrán obtener el registro durante 2 años.
A5: 5.1 Causales generales — Apartado A (rubros A, AA, AAA y Socio Comercial)
A6: 1 | B6: N/A | C6: No desvirtuar las inconsistencias que generaron un requerimiento (regla 7.2.2) | D6: 7.2.4 Apt. A, fracc. I
A7: 2 | B7: N/A | C7: No presentar los avisos establecidos en la regla 7.2.1 | D7: 7.2.4 Apt. A, fracc. II
A8: 3 | B8: N/A | C8: No acreditar durante la inspección de supervisión que se cuenta con la infraestructura necesaria para las actividades autorizadas | D8: 7.2.4 Apt. A, fracc. III
A9: 4 | B9: N/A | C9: No llevar el sistema de control de inventarios de forma automatizada | D9: 7.2.4 Apt. A, fracc. IV
A10: 5 | B10: N/A | C10: Presentar o declarar documentación o información falsa, alterada o con datos falsos en cualquier trámite o en operaciones de comercio exterior | D10: 7.2.4 Apt. A, fracc. V
A11: 6 | B11: N/A | C11: El SAT interponga querella, denuncia penal o declaratoria de perjuicio contra socios, accionistas, representante legal o integrantes de la administración | D11: 7.2.4 Apt. A, fracc. VI
A12: 7 | B12: N/A | C12: Contribuyente no localizado en domicilio fiscal o establecimientos no localizados/inexistentes | D12: 7.2.4 Apt. A, fracc. VII
A13: 8 | B13: N/A | C13: Importar temporalmente mercancías del Anexo II del Decreto IMMEX sin autorización, o importar fracciones que no corresponden al proceso productivo | D13: 7.2.4 Apt. A, fracc. VIII
A14: 9 | B14: N/A | C14: Socios/accionistas, representante legal o administración vinculados con empresa a quien se le canceló el registro (fracc. V, VI, VII Apt. A o II, III Apt. B) | D14: 7.2.4 Apt. A, fracc. IX
A15: 10 | B15: N/A | C15: Nombre o domicilio del proveedor/productor, destinatario o comprador en pedimentos, CFDI o información proporcionada sean falsos, inexistentes o no localizados | D15: 7.2.4 Apt. A, fracc. X
A16: 5.2 Causales específicas IVA e IEPS — Apartado B (rubros A, AA, AAA)
A17: 11 | B17: N/A | C17: Cancelación definitiva de la autorización, permiso o régimen aduanero bajo el cual se otorgó el registro (ej. cancelación definitiva del Programa IMMEX) | D17: 7.2.4 Apt. B, fracc. I
A18: 12 | B18: N/A | C18: Empresas IMMEX: mercancías importadas temporalmente no retornadas, transferidas ni destinadas a otro régimen dentro del plazo autorizado | D18: 7.2.4 Apt. B, fracc. II
A19: 13 | B19: N/A | C19: Las autoridades aduaneras detectan que las mercancías importadas temporalmente no se encuentran en los domicilios autorizados | D19: 7.2.4 Apt. B, fracc. III
A20: 14 | B20: N/A | C20: No acreditar la legal estancia de mercancías de comercio exterior por más de $100,000 pesos y no cubrir el crédito fiscal determinado y notificado por el SAT | D20: 7.2.4 Apt. B, fracc. IV
A21: 15 | B21: N/A | C21: Suspensión definitiva confirmada en el Padrón de Importadores o padrones específicos/sectoriales | D21: 7.2.4 Apt. B, fracc. V
A22: 16 | B22: N/A | C22: La AGACE constata (inspección o facultades de comprobación) que no cuenta con infraestructura para operar el Programa IMMEX/RFE/depósito fiscal; incumple proceso productivo o no tiene la inversión declarada | D22: 7.2.4 Apt. B, fracc. VI
A23: 17 | B23: N/A | C23: No haber retornado mercancías importadas temporalmente conforme a los porcentajes de la regla 7.1.2 (Apartados A fracc. III y B) | D23: 7.2.4 Apt. B, fracc. VII
A24: 5.3 Causales de suspensión del registro
A25: 18 | B25: N/A | C25: Suspensión del Programa IMMEX por parte de la SE (el registro se suspende mientras dure; si se cancela el IMMEX, se inicia cancelación del registro) | D25: 7.2.4 Suspensión, fracc. I
A26: 19 | B26: N/A | C26: Clave en el RFC suspendida por la autoridad competente (hasta que la autoridad resuelva la situación) | D26: 7.2.4 Suspensión, fracc. II
A27: 20 | B27: N/A | C27: Impedir el acceso a la AGACE para llevar a cabo la supervisión de cumplimiento, sin solicitar nueva fecha dentro de los 15 días siguientes | D27: 7.2.4 Suspensión, fracc. III

Sheet Datos
A1: Sección | B1: Pendiente | C1: Cumplido | D1: En riesgo | E1: N/A | F1: Total
A2: 1. Req. Generales | B2: =COUNTIF(Req_Generales!B:B,"Pendiente") -> 22 | C2: =COUNTIF(Req_Generales!B:B,"Cumplido") -> 0 | D2: =COUNTIF(Req_Generales!B:B,"En riesgo") -> 0 | E2: =COUNTIF(Req_Generales!B:B,"N/A") -> 0 | F2: =SUM(B2:E2) -> 22
A3: 2. Req. Rubro | B3: =COUNTIF(Req_Rubro!B:B,"Pendiente") -> 16 | C3: =COUNTIF(Req_Rubro!B:B,"Cumplido") -> 0 | D3: =COUNTIF(Req_Rubro!B:B,"En riesgo") -> 0 | E3: =COUNTIF(Req_Rubro!B:B,"N/A") -> 0 | F3: =SUM(B3:E3) -> 16
A4: 6. Solicitud 61/LA | B4: =COUNTIF(Solicitud_61LA!B:B,"Pendiente") -> 47 | C4: =COUNTIF(Solicitud_61LA!B:B,"Cumplido") -> 0 | D4: =COUNTIF(Solicitud_61LA!B:B,"En riesgo") -> 0 | E4: =COUNTIF(Solicitud_61LA!B:B,"N/A") -> 16 | F4: =SUM(B4:E4) -> 63
A6: TOTAL | B6: =SUM(B2:B4) -> 85 | C6: =SUM(C2:C4) -> 0 | D6: =SUM(D2:D4) -> 0 | E6: =SUM(E2:E4) -> 16 | F6: =SUM(F2:F4) -> 101
A9: Estado | B9: Cantidad
A10: Pendiente | B10: =B6 -> 85
A11: Cumplido | B11: =C6 -> 0
A12: En riesgo | B12: =D6 -> 0
A15: Responsable | B15: Cantidad
A16: Cliente | B16: =COUNTIF(Req_Generales!F:F,"Cliente")+COUNTIF(Req_Rubro!F:F,"Cliente")+COUNTIF(Solicitud_61LA!F:F,"Cliente") -> 0
A17: Asesor Russell Bedford | B17: =COUNTIF(Req_Generales!F:F,"Asesor Russell Bedford")+COUNTIF(Req_Rubro!F:F,"Asesor Russell Bedford")+COUNTIF(Solicitud_61LA!F:F,"Asesor Russell Bedford") -> 0
A18: AGACE | B18: =COUNTIF(Req_Generales!F:F,"AGACE")+COUNTIF(Req_Rubro!F:F,"AGACE")+COUNTIF(Solicitud_61LA!F:F,"AGACE") -> 0
A19: Otro | B19: =COUNTIF(Req_Generales!F:F,"Otro")+COUNTIF(Req_Rubro!F:F,"Otro")+COUNTIF(Solicitud_61LA!F:F,"Otro") -> 0
